Workbook

Sheet Bestand
A1: Hardware bestand | B1: Ist Bestand | C1: Nicht nutzbar/ Defekt | D1: Zusatzinfo | F1: Summe nutzbar
A2: Laptop | B2: 33 | C2: 1 | D2: 1 offline Server | F2: 32
A3: Kartendrucker | B3: 12 | D3: 1 (zum. Testen im Techniklager) | F3: 12
A4: Laserdrucker (HP) | B4: 7 | F4: 7
A5: Laserdrucker (Kyrocera) | B5: 4 | F5: 4
A6: Laserdrucker (weiß) | B6: 2 | D6: Nicht für Akkreditierung nutzbar | F6: 2
A7: Laserdrucker (Brother) | B7: 20 | F7: 20
A8: Gesamt Laserdrucker | F8: =SUM(F4:F7) -> 33
A9: Thermodrucker | B9: 12 | F9: 12
A10: Scanner | B10: 31 | C10: 2 | D10: Funktion nicht bekannt | F10: 29
A11: Handhelden | B11: 24 | F11: 24
A12: Ipad | B12: 34 | C12: 3 | D12: Im Wersewerk eingesetzt | F12: 31
A13: LTE Gateway | B13: 9 | D13: laden automatisch auf ab 5 € | F13: 9
A14: Switch | B14: 7 | F14: 7

Sheet  MASTER KW 1 (29.12. 04.01.)
A1: Kunde
A2: Mitarbeiter
A3: Gesamtübersicht | B3: =IF(SUM(B5:B13)>0, $A$4&CHAR(10)& IF(B5>0," - "&B5&" x Router"&CHAR(10),"")& IF(B6>0," - "&B6&" x Switch"&CHAR(10),"")& IF(B7>0," - "&B7&" x Laptops"&CHAR(10),"")& IF(B8>0," - "&B8&" x Kartendrucker"&CHAR(10),"")& IF(B13>0," - "&B13&" x iPad"&CHAR(10),"")& IF(B9>0," - "&B9&" x Laserdrucker"&CHAR(10),"")& IF(B10>0," - "&B10&" x Thermodrucker"&CHAR(10),"")& IF(B11>0," - "&B11&" x Scanner"&CHAR(10),"")& IF(B12>0," - "&B12&" x Handheld Scanner"&CHAR(10),""), "")& IF(SUM(B15:B23)>0, $A$14&CHAR(10)& IF(B15>0," - "&B15&" x Router"&CHAR(10),"")& IF(B16>0," - "&B16&" x Switch"&CHAR(10),"")& IF(B17>0," - "&B17&" x Laptops"&CHAR(10),"")& IF(B18>0," - "&B18&" x Kartendrucker"&CHAR(10),"")& IF(B23>0," - "&B23&" x iPad"&CHAR(10),"")& IF(B19>0," - "&B19&" x Laserdrucker"&CHAR(10),"")& IF(B20>0," - "&B20&" x Thermodrucker"&CHAR(10),"")& IF(B21>0," - "&B21&" x Scanner"&CHAR(10),"")& IF(B22>0," - "&B22&" x Handheld Scanner"&CHAR(10),""), "")& IF(SUM(B25:B33)>0, $A$24&CHAR(10)& IF(B25>0," - "&B25&" x Router"&CHAR(10),"")& IF(B26>0," - "&B26&" x Switch"&CHAR(10),"")& IF(B27>0," - "&B27&" x Laptops"&CHAR(10),"")& IF(B28>0," - "&B28&" x Kartendrucker"&CHAR(10),"")& IF(B33>0," - "&B33&" x iPad"&CHAR(10),"")& IF(B29>0," - "&B29&" x Laserdrucker"&CHAR(10),"")& IF(B30>0," - "&B30&" x Thermodrucker"&CHAR(10),"")& IF(B31>0," - "&B31&" x Scanner"&CHAR(10),"")& IF(B32>0," - "&B32&" x Handheld Scanner"&CHAR(10),""), "")& IF(SUM(B35:B43)>0, $A$34&CHAR(10)& IF(B35>0," - "&B35&" x Router"&CHAR(10),"")& IF(B36>0," - "&B36&" x Switch"&CHAR(10),"")& IF(B37>0," - "&B37&" x Laptops"&CHAR(10),"")& IF(B38>0," - "&B38&" x Kartendrucker"&CHAR(10),"")& IF(B43>0," - "&B43&" x iPad"&CHAR(10),"")& IF(B39>0," - "&B39&" x Laserdrucker"&CHAR(10),"")& IF(B40>0," - "&B40&" x Thermodrucker"&CHAR(10),"")& IF(B41>0," - "&B41&" x Scanner"&CHAR(10),"")& IF(B42>0," - "&B42&" x Handheld Scanner"&CHAR(10),""), "")& IF(SUM(B45:B53)>0, $A$44&CHAR(10)& IF(B45>0," - "&B45&" x Router"&CHAR(10),"")& IF(B46>0," - "&B46&" x Switch"&CHAR(10),"")& IF(B47>0," - "&B47&" x Laptops"&CHAR(10),"")& IF(B48>0," - "&B48&" x Kartendrucker"&CHAR(10),"")& IF(B53>0," - "&B53&" x iPad"&CHAR(10),"")& IF(B49>0," - "&B49&" x Laserdrucker"&CHAR(10),"")& IF(B50>0," - "&B50&" x Thermodrucker"&CHAR(10),"")& IF(B51>0," - "&B51&" x Scanner"&CHAR(10),"")& IF(B52>0," - "&B52&" x Handheld Scanner"&CHAR(10),""), "")& IF(SUM(B55:B63)>0, $A$54&CHAR(10)& IF(B55>0," - "&B55&" x Router"&CHAR(10),"")& IF(B56>0," - "&B56&" x Switch"&CHAR(10),"")& IF(B57>0," - "&B57&" x Laptops"&CHAR(10),"")& IF(B58>0," - "&B58&" x Kartendrucker"&CHAR(10),"")& IF(B63>0," - "&B63&" x iPad"&CHAR(10),"")& IF(B59>0," - "&B59&" x Laserdrucker"&CHAR(10),"")& IF(B60>0," - "&B60&" x Thermodrucker"&CHAR(10),"")& IF(B61>0," - "&B61&" x Scanner"&CHAR(10),"")& IF(B62>0," - "&B62&" x Handheld Scanner"&CHAR(10),""), "")& IF(SUM(B65:B73)>0, $A$64&CHAR(10)& IF(B65>0," - "&B65&" x Router"&CHAR(10),"")& IF(B66>0," - "&B66&" x Switch"&CHAR(10),"")& IF(B67>0," - "&B67&" x Laptops"&CHAR(10),"")& IF(B68>0," - "&B68&" x Kartendrucker"&CHAR(10),"")& IF(B73>0," - "&B73&" x iPad"&CHAR(10),"")& IF(B69>0," - "&B69&" x Laserdrucker"&CHAR(10),"")& IF(B70>0," - "&B70&" x Thermodrucker"&CHAR(10),"")& IF(B71>0," - "&B71&" x Scanner"&CHAR(10),"")& IF(B72>0," - "&B72&" x Handheld Scanner"&CHAR(10),""), "") | C3: =IF(SUM(C5:C13)>0, $A$4&CHAR(10)& IF(C5>0," - "&C5&" x Router"&CHAR(10),"")& IF(C6>0," - "&C6&" x Switch"&CHAR(10),"")& IF(C7>0," - "&C7&" x Laptops"&CHAR(10),"")& IF(C8>0," - "&C8&" x Kartendrucker"&CHAR(10),"")& IF(C13>0," - "&C13&" x iPad"&CHAR(10),"")& IF(C9>0," - "&C9&" x Laserdrucker"&CHAR(10),"")& IF(C10>0," - "&C10&" x Thermodrucker"&CHAR(10),"")& IF(C11>0," - "&C11&" x Scanner"&CHAR(10),"")& IF(C12>0," - "&C12&" x Handheld Scanner"&CHAR(10),""), "")& IF(SUM(C15:C23)>0, $A$14&CHAR(10)& IF(C15>0," - "&C15&" x Router"&CHAR(10),"")& IF(C16>0," - "&C16&" x Switch"&CHAR(10),"")& IF(C17>0," - "&C17&" x Laptops"&CHAR(10),"")& IF(C18>0," - "&C18&" x Kartendrucker"&CHAR(10),"")& IF(C23>0," - "&C23&" x iPad"&CHAR(10),"")& IF(C19>0," - "&C19&" x Laserdrucker"&CHAR(10),"")& IF(C20>0," - "&C20&" x Thermodrucker"&CHAR(10),"")& IF(C21>0," - "&C21&" x Scanner"&CHAR(10),"")& IF(C22>0," - "&C22&" x Handheld Scanner"&CHAR(10),""), "")& IF(SUM(C25:C33)>0, $A$24&CHAR(10)& IF(C25>0," - "&C25&" x Router"&CHAR(10),"")& IF(C26>0," - "&C26&" x Switch"&CHAR(10),"")& IF(C27>0," - "&C27&" x Laptops"&CHAR(10),"")& IF(C28>0," - "&C28&" x Kartendrucker"&CHAR(10),"")& IF(C33>0," - "&C33&" x iPad"&CHAR(10),"")& IF(C29>0," - "&C29&" x Laserdrucker"&CHAR(10),"")& IF(C30>0," - "&C30&" x Thermodrucker"&CHAR(10),"")& IF(C31>0," - "&C31&" x Scanner"&CHAR(10),"")& IF(C32>0," - "&C32&" x Handheld Scanner"&CHAR(10),""), "")& IF(SUM(C35:C43)>0, $A$34&CHAR(10)& IF(C35>0," - "&C35&" x Router"&CHAR(10),"")& IF(C36>0," - "&C36&" x Switch"&CHAR(10),"")& IF(C37>0," - "&C37&" x Laptops"&CHAR(10),"")& IF(C38>0," - "&C38&" x Kartendrucker"&CHAR(10),"")& IF(C43>0," - "&C43&" x iPad"&CHAR(10),"")& IF(C39>0," - "&C39&" x Laserdrucker"&CHAR(10),"")& IF(C40>0," - "&C40&" x Thermodrucker"&CHAR(10),"")& IF(C41>0," - "&C41&" x Scanner"&CHAR(10),"")& IF(C42>0," - "&C42&" x Handheld Scanner"&CHAR(10),""), "")& IF(SUM(C45:C53)>0, $A$44&CHAR(10)& IF(C45>0," - "&C45&" x Router"&CHAR(10),"")& IF(C46>0," - "&C46&" x Switch"&CHAR(10),"")& IF(C47>0," - "&C47&" x Laptops"&CHAR(10),"")& IF(C48>0," - "&C48&" x Kartendrucker"&CHAR(10),"")& IF(C53>0," - "&C53&" x iPad"&CHAR(10),"")& IF(C49>0," - "&C49&" x Laserdrucker"&CHAR(10),"")& IF(C50>0," - "&C50&" x Thermodrucker"&CHAR(10),"")& IF(C51>0," - "&C51&" x Scanner"&CHAR(10),"")& IF(C52>0," - "&C52&" x Handheld Scanner"&CHAR(10),""), "")& IF(SUM(C55:C63)>0, $A$54&CHAR(10)& IF(C55>0," - "&C55&" x Router"&CHAR(10),"")& IF(C56>0," - "&C56&" x Switch"&CHAR(10),"")& IF(C57>0," - "&C57&" x Laptops"&CHAR(10),"")& IF(C58>0," - "&C58&" x Kartendrucker"&CHAR(10),"")& IF(C63>0," - "&C63&" x iPad"&CHAR(10),"")& IF(C59>0," - "&C59&" x Laserdrucker"&CHAR(10),"")& IF(C60>0," - "&C60&" x Thermodrucker"&CHAR(10),"")& IF(C61>0," - "&C61&" x Scanner"&CHAR(10),"")& IF(C62>0," - "&C62&" x Handheld Scanner"&CHAR(10),""), "")& IF(SUM(C65:C73)>0, $A$64&CHAR(10)& IF(C65>0," - "&C65&" x Router"&CHAR(10),"")& IF(C66>0," - "&C66&" x Switch"&CHAR(10),"")& IF(C67>0," - "&C67&" x Laptops"&CHAR(10),"")& IF(C68>0," - "&C68&" x Kartendrucker"&CHAR(10),"")& IF(C73>0," - "&C73&" x iPad"&CHAR(10),"")& IF(C69>0," - "&C69&" x Laserdrucker"&CHAR(10),"")& IF(C70>0," - "&C70&" x Thermodrucker"&CHAR(10),"")& IF(C71>0," - "&C71&" x Scanner"&CHAR(10),"")& IF(C72>0," - "&C72&" x Handheld Scanner"&CHAR(10),""), "") | D3: =IF(SUM(D5:D13)>0, $A$4&CHAR(10)& IF(D5>0," - "&D5&" x Router"&CHAR(10),"")& IF(D6>0," - "&D6&" x Switch"&CHAR(10),"")& IF(D7>0," - "&D7&" x Laptops"&CHAR(10),"")& IF(D8>0," - "&D8&" x Kartendrucker"&CHAR(10),"")& IF(D13>0," - "&D13&" x iPad"&CHAR(10),"")& IF(D9>0," - "&D9&" x Laserdrucker"&CHAR(10),"")& IF(D10>0," - "&D10&" x Thermodrucker"&CHAR(10),"")& IF(D11>0," - "&D11&" x Scanner"&CHAR(10),"")& IF(D12>0," - "&D12&" x Handheld Scanner"&CHAR(10),""), "")& IF(SUM(D15:D23)>0, $A$14&CHAR(10)& IF(D15>0," - "&D15&" x Router"&CHAR(10),"")& IF(D16>0," - "&D16&" x Switch"&CHAR(10),"")& IF(D17>0," - "&D17&" x Laptops"&CHAR(10),"")& IF(D18>0," - "&D18&" x Kartendrucker"&CHAR(10),"")& IF(D23>0," - "&D23&" x iPad"&CHAR(10),"")& IF(D19>0," - "&D19&" x Laserdrucker"&CHAR(10),"")& IF(D20>0," - "&D20&" x Thermodrucker"&CHAR(10),"")& IF(D21>0," - "&D21&" x Scanner"&CHAR(10),"")& IF(D22>0," - "&D22&" x Handheld Scanner"&CHAR(10),""), "")& IF(SUM(D25:D33)>0, $A$24&CHAR(10)& IF(D25>0," - "&D25&" x Router"&CHAR(10),"")& IF(D26>0," - "&D26&" x Switch"&CHAR(10),"")& IF(D27>0," - "&D27&" x Laptops"&CHAR(10),"")& IF(D28>0," - "&D28&" x Kartendrucker"&CHAR(10),"")& IF(D33>0," - "&D33&" x iPad"&CHAR(10),"")& IF(D29>0," - "&D29&" x Laserdrucker"&CHAR(10),"")& IF(D30>0," - "&D30&" x Thermodrucker"&CHAR(10),"")& IF(D31>0," - "&D31&" x Scanner"&CHAR(10),"")& IF(D32>0," - "&D32&" x Handheld Scanner"&CHAR(10),""), "")& IF(SUM(D35:D43)>0, $A$34&CHAR(10)& IF(D35>0," - "&D35&" x Router"&CHAR(10),"")& IF(D36>0," - "&D36&" x Switch"&CHAR(10),"")& IF(D37>0," - "&D37&" x Laptops"&CHAR(10),"")& IF(D38>0," - "&D38&" x Kartendrucker"&CHAR(10),"")& IF(D43>0," - "&D43&" x iPad"&CHAR(10),"")& IF(D39>0," - "&D39&" x Laserdrucker"&CHAR(10),"")& IF(D40>0," - "&D40&" x Thermodrucker"&CHAR(10),"")& IF(D41>0," - "&D41&" x Scanner"&CHAR(10),"")& IF(D42>0," - "&D42&" x Handheld Scanner"&CHAR(10),""), "")& IF(SUM(D45:D53)>0, $A$44&CHAR(10)& IF(D45>0," - "&D45&" x Router"&CHAR(10),"")& IF(D46>0," - "&D46&" x Switch"&CHAR(10),"")& IF(D47>0," - "&D47&" x Laptops"&CHAR(10),"")& IF(D48>0," - "&D48&" x Kartendrucker"&CHAR(10),"")& IF(D53>0," - "&D53&" x iPad"&CHAR(10),"")& IF(D49>0," - "&D49&" x Laserdrucker"&CHAR(10),"")& IF(D50>0," - "&D50&" x Thermodrucker"&CHAR(10),"")& IF(D51>0," - "&D51&" x Scanner"&CHAR(10),"")& IF(D52>0," - "&D52&" x Handheld Scanner"&CHAR(10),""), "")& IF(SUM(D55:D63)>0, $A$54&CHAR(10)& IF(D55>0," - "&D55&" x Router"&CHAR(10),"")& IF(D56>0," - "&D56&" x Switch"&CHAR(10),"")& IF(D57>0," - "&D57&" x Laptops"&CHAR(10),"")& IF(D58>0," - "&D58&" x Kartendrucker"&CHAR(10),"")& IF(D63>0," - "&D63&" x iPad"&CHAR(10),"")& IF(D59>0," - "&D59&" x Laserdrucker"&CHAR(10),"")& IF(D60>0," - "&D60&" x Thermodrucker"&CHAR(10),"")& IF(D61>0," - "&D61&" x Scanner"&CHAR(10),"")& IF(D62>0," - "&D62&" x Handheld Scanner"&CHAR(10),""), "")& IF(SUM(D65:D73)>0, $A$64&CHAR(10)& IF(D65>0," - "&D65&" x Router"&CHAR(10),"")& IF(D66>0," - "&D66&" x Switch"&CHAR(10),"")& IF(D67>0," - "&D67&" x Laptops"&CHAR(10),"")& IF(D68>0," - "&D68&" x Kartendrucker"&CHAR(10),"")& IF(D73>0," - "&D73&" x iPad"&CHAR(10),"")& IF(D69>0," - "&D69&" x Laserdrucker"&CHAR(10),"")& IF(D70>0," - "&D70&" x Thermodrucker"&CHAR(10),"")& IF(D71>0," - "&D71&" x Scanner"&CHAR(10),"")& IF(D72>0," - "&D72&" x Handheld Scanner"&CHAR(10),""), "") | E3: =IF(SUM(E5:E13)>0, $A$4&CHAR(10)& IF(E5>0," - "&E5&" x Router"&CHAR(10),"")& IF(E6>0," - "&E6&" x Switch"&CHAR(10),"")& IF(E7>0," - "&E7&" x Laptops"&CHAR(10),"")& IF(E8>0," - "&E8&" x Kartendrucker"&CHAR(10),"")& IF(E13>0," - "&E13&" x iPad"&CHAR(10),"")& IF(E9>0," - "&E9&" x Laserdrucker"&CHAR(10),"")& IF(E10>0," - "&E10&" x Thermodrucker"&CHAR(10),"")& IF(E11>0," - "&E11&" x Scanner"&CHAR(10),"")& IF(E12>0," - "&E12&" x Handheld Scanner"&CHAR(10),""), "")& IF(SUM(E15:E23)>0, $A$14&CHAR(10)& IF(E15>0," - "&E15&" x Router"&CHAR(10),"")& IF(E16>0," - "&E16&" x Switch"&CHAR(10),"")& IF(E17>0," - "&E17&" x Laptops"&CHAR(10),"")& IF(E18>0," - "&E18&" x Kartendrucker"&CHAR(10),"")& IF(E23>0," - "&E23&" x iPad"&CHAR(10),"")& IF(E19>0," - "&E19&" x Laserdrucker"&CHAR(10),"")& IF(E20>0," - "&E20&" x Thermodrucker"&CHAR(10),"")& IF(E21>0," - "&E21&" x Scanner"&CHAR(10),"")& IF(E22>0," - "&E22&" x Handheld Scanner"&CHAR(10),""), "")& IF(SUM(E25:E33)>0, $A$24&CHAR(10)& IF(E25>0," - "&E25&" x Router"&CHAR(10),"")& IF(E26>0," - "&E26&" x Switch"&CHAR(10),"")& IF(E27>0," - "&E27&" x Laptops"&CHAR(10),"")& IF(E28>0," - "&E28&" x Kartendrucker"&CHAR(10),"")& IF(E33>0," - "&E33&" x iPad"&CHAR(10),"")& IF(E29>0," - "&E29&" x Laserdrucker"&CHAR(10),"")& IF(E30>0," - "&E30&" x Thermodrucker"&CHAR(10),"")& IF(E31>0," - "&E31&" x Scanner"&CHAR(10),"")& IF(E32>0," - "&E32&" x Handheld Scanner"&CHAR(10),""), "")& IF(SUM(E35:E43)>0, $A$34&CHAR(10)& IF(E35>0," - "&E35&" x Router"&CHAR(10),"")& IF(E36>0," - "&E36&" x Switch"&CHAR(10),"")& IF(E37>0," - "&E37&" x Laptops"&CHAR(10),"")& IF(E38>0," - "&E38&" x Kartendrucker"&CHAR(10),"")& IF(E43>0," - "&E43&" x iPad"&CHAR(10),"")& IF(E39>0," - "&E39&" x Laserdrucker"&CHAR(10),"")& IF(E40>0," - "&E40&" x Thermodrucker"&CHAR(10),"")& IF(E41>0," - "&E41&" x Scanner"&CHAR(10),"")& IF(E42>0," - "&E42&" x Handheld Scanner"&CHAR(10),""), "")& IF(SUM(E45:E53)>0, $A$44&CHAR(10)& IF(E45>0," - "&E45&" x Router"&CHAR(10),"")& IF(E46>0," - "&E46&" x Switch"&CHAR(10),"")& IF(E47>0," - "&E47&" x Laptops"&CHAR(10),"")& IF(E48>0," - "&E48&" x Kartendrucker"&CHAR(10),"")& IF(E53>0," - "&E53&" x iPad"&CHAR(10),"")& IF(E49>0," - "&E49&" x Laserdrucker"&CHAR(10),"")& IF(E50>0," - "&E50&" x Thermodrucker"&CHAR(10),"")& IF(E51>0," - "&E51&" x Scanner"&CHAR(10),"")& IF(E52>0," - "&E52&" x Handheld Scanner"&CHAR(10),""), "")& IF(SUM(E55:E63)>0, $A$54&CHAR(10)& IF(E55>0," - "&E55&" x Router"&CHAR(10),"")& IF(E56>0," - "&E56&" x Switch"&CHAR(10),"")& IF(E57>0," - "&E57&" x Laptops"&CHAR(10),"")& IF(E58>0," - "&E58&" x Kartendrucker"&CHAR(10),"")& IF(E63>0," - "&E63&" x iPad"&CHAR(10),"")& IF(E59>0," - "&E59&" x Laserdrucker"&CHAR(10),"")& IF(E60>0," - "&E60&" x Thermodrucker"&CHAR(10),"")& IF(E61>0," - "&E61&" x Scanner"&CHAR(10),"")& IF(E62>0," - "&E62&" x Handheld Scanner"&CHAR(10),""), "")& IF(SUM(E65:E73)>0, $A$64&CHAR(10)& IF(E65>0," - "&E65&" x Router"&CHAR(10),"")& IF(E66>0," - "&E66&" x Switch"&CHAR(10),"")& IF(E67>0," - "&E67&" x Laptops"&CHAR(10),"")& IF(E68>0," - "&E68&" x Kartendrucker"&CHAR(10),"")& IF(E73>0," - "&E73&" x iPad"&CHAR(10),"")& IF(E69>0," - "&E69&" x Laserdrucker"&CHAR(10),"")& IF(E70>0," - "&E70&" x Thermodrucker"&CHAR(10),"")& IF(E71>0," - "&E71&" x Scanner"&CHAR(10),"")& IF(E72>0," - "&E72&" x Handheld Scanner"&CHAR(10),""), "") | F3: =IF(SUM(F5:F13)>0, $A$4&CHAR(10)& IF(F5>0," - "&F5&" x Router"&CHAR(10),"")& IF(F6>0," - "&F6&" x Switch"&CHAR(10),"")& IF(F7>0," - "&F7&" x Laptops"&CHAR(10),"")& IF(F8>0," - "&F8&" x Kartendrucker"&CHAR(10),"")& IF(F13>0," - "&F13&" x iPad"&CHAR(10),"")& IF(F9>0," - "&F9&" x Laserdrucker"&CHAR(10),"")& IF(F10>0," - "&F10&" x Thermodrucker"&CHAR(10),"")& IF(F11>0," - "&F11&" x Scanner"&CHAR(10),"")& IF(F12>0," - "&F12&" x Handheld Scanner"&CHAR(10),""), "")& IF(SUM(F15:F23)>0, $A$14&CHAR(10)& IF(F15>0," - "&F15&" x Router"&CHAR(10),"")& IF(F16>0," - "&F16&" x Switch"&CHAR(10),"")& IF(F17>0," - "&F17&" x Laptops"&CHAR(10),"")& IF(F18>0," - "&F18&" x Kartendrucker"&CHAR(10),"")& IF(F23>0," - "&F23&" x iPad"&CHAR(10),"")& IF(F19>0," - "&F19&" x Laserdrucker"&CHAR(10),"")& IF(F20>0," - "&F20&" x Thermodrucker"&CHAR(10),"")& IF(F21>0," - "&F21&" x Scanner"&CHAR(10),"")& IF(F22>0," - "&F22&" x Handheld Scanner"&CHAR(10),""), "")& IF(SUM(F25:F33)>0, $A$24&CHAR(10)& IF(F25>0," - "&F25&" x Router"&CHAR(10),"")& IF(F26>0," - "&F26&" x Switch"&CHAR(10),"")& IF(F27>0," - "&F27&" x Laptops"&CHAR(10),"")& IF(F28>0," - "&F28&" x Kartendrucker"&CHAR(10),"")& IF(F33>0," - "&F33&" x iPad"&CHAR(10),"")& IF(F29>0," - "&F29&" x Laserdrucker"&CHAR(10),"")& IF(F30>0," - "&F30&" x Thermodrucker"&CHAR(10),"")& IF(F31>0," - "&F31&" x Scanner"&CHAR(10),"")& IF(F32>0," - "&F32&" x Handheld Scanner"&CHAR(10),""), "")& IF(SUM(F35:F43)>0, $A$34&CHAR(10)& IF(F35>0," - "&F35&" x Router"&CHAR(10),"")& IF(F36>0," - "&F36&" x Switch"&CHAR(10),"")& IF(F37>0," - "&F37&" x Laptops"&CHAR(10),"")& IF(F38>0," - "&F38&" x Kartendrucker"&CHAR(10),"")& IF(F43>0," - "&F43&" x iPad"&CHAR(10),"")& IF(F39>0," - "&F39&" x Laserdrucker"&CHAR(10),"")& IF(F40>0," - "&F40&" x Thermodrucker"&CHAR(10),"")& IF(F41>0," - "&F41&" x Scanner"&CHAR(10),"")& IF(F42>0," - "&F42&" x Handheld Scanner"&CHAR(10),""), "")& IF(SUM(F45:F53)>0, $A$44&CHAR(10)& IF(F45>0," - "&F45&" x Router"&CHAR(10),"")& IF(F46>0," - "&F46&" x Switch"&CHAR(10),"")& IF(F47>0," - "&F47&" x Laptops"&CHAR(10),"")& IF(F48>0," - "&F48&" x Kartendrucker"&CHAR(10),"")& IF(F53>0," - "&F53&" x iPad"&CHAR(10),"")& IF(F49>0," - "&F49&" x Laserdrucker"&CHAR(10),"")& IF(F50>0," - "&F50&" x Thermodrucker"&CHAR(10),"")& IF(F51>0," - "&F51&" x Scanner"&CHAR(10),"")& IF(F52>0," - "&F52&" x Handheld Scanner"&CHAR(10),""), "")& IF(SUM(F55:F63)>0, $A$54&CHAR(10)& IF(F55>0," - "&F55&" x Router"&CHAR(10),"")& IF(F56>0," - "&F56&" x Switch"&CHAR(10),"")& IF(F57>0," - "&F57&" x Laptops"&CHAR(10),"")& IF(F58>0," - "&F58&" x Kartendrucker"&CHAR(10),"")& IF(F63>0," - "&F63&" x iPad"&CHAR(10),"")& IF(F59>0," - "&F59&" x Laserdrucker"&CHAR(10),"")& IF(F60>0," - "&F60&" x Thermodrucker"&CHAR(10),"")& IF(F61>0," - "&F61&" x Scanner"&CHAR(10),"")& IF(F62>0," - "&F62&" x Handheld Scanner"&CHAR(10),""), "")& IF(SUM(F65:F73)>0, $A$64&CHAR(10)& IF(F65>0," - "&F65&" x Router"&CHAR(10),"")& IF(F66>0," - "&F66&" x Switch"&CHAR(10),"")& IF(F67>0," - "&F67&" x Laptops"&CHAR(10),"")& IF(F68>0," - "&F68&" x Kartendrucker"&CHAR(10),"")& IF(F73>0," - "&F73&" x iPad"&CHAR(10),"")& IF(F69>0," - "&F69&" x Laserdrucker"&CHAR(10),"")& IF(F70>0," - "&F70&" x Thermodrucker"&CHAR(10),"")& IF(F71>0," - "&F71&" x Scanner"&CHAR(10),"")& IF(F72>0," - "&F72&" x Handheld Scanner"&CHAR(10),""), "") | G3: =IF(SUM(G5:G13)>0, $A$4&CHAR(10)& IF(G5>0," - "&G5&" x Router"&CHAR(10),"")& IF(G6>0," - "&G6&" x Switch"&CHAR(10),"")& IF(G7>0," - "&G7&" x Laptops"&CHAR(10),"")& IF(G8>0," - "&G8&" x Kartendrucker"&CHAR(10),"")& IF(G13>0," - "&G13&" x iPad"&CHAR(10),"")& IF(G9>0," - "&G9&" x Laserdrucker"&CHAR(10),"")& IF(G10>0," - "&G10&" x Thermodrucker"&CHAR(10),"")& IF(G11>0," - "&G11&" x Scanner"&CHAR(10),"")& IF(G12>0," - "&G12&" x Handheld Scanner"&CHAR(10),""), "")& IF(SUM(G15:G23)>0, $A$14&CHAR(10)& IF(G15>0," - "&G15&" x Router"&CHAR(10),"")& IF(G16>0," - "&G16&" x Switch"&CHAR(10),"")& IF(G17>0," - "&G17&" x Laptops"&CHAR(10),"")& IF(G18>0," - "&G18&" x Kartendrucker"&CHAR(10),"")& IF(G23>0," - "&G23&" x iPad"&CHAR(10),"")& IF(G19>0," - "&G19&" x Laserdrucker"&CHAR(10),"")& IF(G20>0," - "&G20&" x Thermodrucker"&CHAR(10),"")& IF(G21>0," - "&G21&" x Scanner"&CHAR(10),"")& IF(G22>0," - "&G22&" x Handheld Scanner"&CHAR(10),""), "")& IF(SUM(G25:G33)>0, $A$24&CHAR(10)& IF(G25>0," - "&G25&" x Router"&CHAR(10),"")& IF(G26>0," - "&G26&" x Switch"&CHAR(10),"")& IF(G27>0," - "&G27&" x Laptops"&CHAR(10),"")& IF(G28>0," - "&G28&" x Kartendrucker"&CHAR(10),"")& IF(G33>0," - "&G33&" x iPad"&CHAR(10),"")& IF(G29>0," - "&G29&" x Laserdrucker"&CHAR(10),"")& IF(G30>0," - "&G30&" x Thermodrucker"&CHAR(10),"")& IF(G31>0," - "&G31&" x Scanner"&CHAR(10),"")& IF(G32>0," - "&G32&" x Handheld Scanner"&CHAR(10),""), "")& IF(SUM(G35:G43)>0, $A$34&CHAR(10)& IF(G35>0," - "&G35&" x Router"&CHAR(10),"")& IF(G36>0," - "&G36&" x Switch"&CHAR(10),"")& IF(G37>0," - "&G37&" x Laptops"&CHAR(10),"")& IF(G38>0," - "&G38&" x Kartendrucker"&CHAR(10),"")& IF(G43>0," - "&G43&" x iPad"&CHAR(10),"")& IF(G39>0," - "&G39&" x Laserdrucker"&CHAR(10),"")& IF(G40>0," - "&G40&" x Thermodrucker"&CHAR(10),"")& IF(G41>0," - "&G41&" x Scanner"&CHAR(10),"")& IF(G42>0," - "&G42&" x Handheld Scanner"&CHAR(10),""), "")& IF(SUM(G45:G53)>0, $A$44&CHAR(10)& IF(G45>0," - "&G45&" x Router"&CHAR(10),"")& IF(G46>0," - "&G46&" x Switch"&CHAR(10),"")& IF(G47>0," - "&G47&" x Laptops"&CHAR(10),"")& IF(G48>0," - "&G48&" x Kartendrucker"&CHAR(10),"")& IF(G53>0," - "&G53&" x iPad"&CHAR(10),"")& IF(G49>0," - "&G49&" x Laserdrucker"&CHAR(10),"")& IF(G50>0," - "&G50&" x Thermodrucker"&CHAR(10),"")& IF(G51>0," - "&G51&" x Scanner"&CHAR(10),"")& IF(G52>0," - "&G52&" x Handheld Scanner"&CHAR(10),""), "")& IF(SUM(G55:G63)>0, $A$54&CHAR(10)& IF(G55>0," - "&G55&" x Router"&CHAR(10),"")& IF(G56>0," - "&G56&" x Switch"&CHAR(10),"")& IF(G57>0," - "&G57&" x Laptops"&CHAR(10),"")& IF(G58>0," - "&G58&" x Kartendrucker"&CHAR(10),"")& IF(G63>0," - "&G63&" x iPad"&CHAR(10),"")& IF(G59>0," - "&G59&" x Laserdrucker"&CHAR(10),"")& IF(G60>0," - "&G60&" x Thermodrucker"&CHAR(10),"")& IF(G61>0," - "&G61&" x Scanner"&CHAR(10),"")& IF(G62>0," - "&G62&" x Handheld Scanner"&CHAR(10),""), "")& IF(SUM(G65:G73)>0, $A$64&CHAR(10)& IF(G65>0," - "&G65&" x Router"&CHAR(10),"")& IF(G66>0," - "&G66&" x Switch"&CHAR(10),"")& IF(G67>0," - "&G67&" x Laptops"&CHAR(10),"")& IF(G68>0," - "&G68&" x Kartendrucker"&CHAR(10),"")& IF(G73>0," - "&G73&" x iPad"&CHAR(10),"")& IF(G69>0," - "&G69&" x Laserdrucker"&CHAR(10),"")& IF(G70>0," - "&G70&" x Thermodrucker"&CHAR(10),"")& IF(G71>0," - "&G71&" x Scanner"&CHAR(10),"")& IF(G72>0," - "&G72&" x Handheld Scanner"&CHAR(10),""), "") | H3: =IF(SUM(H5:H13)>0, $A$4&CHAR(10)& IF(H5>0," - "&H5&" x Router"&CHAR(10),"")& IF(H6>0," - "&H6&" x Switch"&CHAR(10),"")& IF(H7>0," - "&H7&" x Laptops"&CHAR(10),"")& IF(H8>0," - "&H8&" x Kartendrucker"&CHAR(10),"")& IF(H13>0," - "&H13&" x iPad"&CHAR(10),"")& IF(H9>0," - "&H9&" x Laserdrucker"&CHAR(10),"")& IF(H10>0," - "&H10&" x Thermodrucker"&CHAR(10),"")& IF(H11>0," - "&H11&" x Scanner"&CHAR(10),"")& IF(H12>0," - "&H12&" x Handheld Scanner"&CHAR(10),""), "")& IF(SUM(H15:H23)>0, $A$14&CHAR(10)& IF(H15>0," - "&H15&" x Router"&CHAR(10),"")& IF(H16>0," - "&H16&" x Switch"&CHAR(10),"")& IF(H17>0," - "&H17&" x Laptops"&CHAR(10),"")& IF(H18>0," - "&H18&" x Kartendrucker"&CHAR(10),"")& IF(H23>0," - "&H23&" x iPad"&CHAR(10),"")& IF(H19>0," - "&H19&" x Laserdrucker"&CHAR(10),"")& IF(H20>0," - "&H20&" x Thermodrucker"&CHAR(10),"")& IF(H21>0," - "&H21&" x Scanner"&CHAR(10),"")& IF(H22>0," - "&H22&" x Handheld Scanner"&CHAR(10),""), "")& IF(SUM(H25:H33)>0, $A$24&CHAR(10)& IF(H25>0," - "&H25&" x Router"&CHAR(10),"")& IF(H26>0," - "&H26&" x Switch"&CHAR(10),"")& IF(H27>0," - "&H27&" x Laptops"&CHAR(10),"")& IF(H28>0," - "&H28&" x Kartendrucker"&CHAR(10),"")& IF(H33>0," - "&H33&" x iPad"&CHAR(10),"")& IF(H29>0," - "&H29&" x Laserdrucker"&CHAR(10),"")& IF(H30>0," - "&H30&" x Thermodrucker"&CHAR(10),"")& IF(H31>0," - "&H31&" x Scanner"&CHAR(10),"")& IF(H32>0," - "&H32&" x Handheld Scanner"&CHAR(10),""), "")& IF(SUM(H35:H43)>0, $A$34&CHAR(10)& IF(H35>0," - "&H35&" x Router"&CHAR(10),"")& IF(H36>0," - "&H36&" x Switch"&CHAR(10),"")& IF(H37>0," - "&H37&" x Laptops"&CHAR(10),"")& IF(H38>0," - "&H38&" x Kartendrucker"&CHAR(10),"")& IF(H43>0," - "&H43&" x iPad"&CHAR(10),"")& IF(H39>0," - "&H39&" x Laserdrucker"&CHAR(10),"")& IF(H40>0," - "&H40&" x Thermodrucker"&CHAR(10),"")& IF(H41>0," - "&H41&" x Scanner"&CHAR(10),"")& IF(H42>0," - "&H42&" x Handheld Scanner"&CHAR(10),""), "")& IF(SUM(H45:H53)>0, $A$44&CHAR(10)& IF(H45>0," - "&H45&" x Router"&CHAR(10),"")& IF(H46>0," - "&H46&" x Switch"&CHAR(10),"")& IF(H47>0," - "&H47&" x Laptops"&CHAR(10),"")& IF(H48>0," - "&H48&" x Kartendrucker"&CHAR(10),"")& IF(H53>0," - "&H53&" x iPad"&CHAR(10),"")& IF(H49>0," - "&H49&" x Laserdrucker"&CHAR(10),"")& IF(H50>0," - "&H50&" x Thermodrucker"&CHAR(10),"")& IF(H51>0," - "&H51&" x Scanner"&CHAR(10),"")& IF(H52>0," - "&H52&" x Handheld Scanner"&CHAR(10),""), "")& IF(SUM(H55:H63)>0, $A$54&CHAR(10)& IF(H55>0," - "&H55&" x Router"&CHAR(10),"")& IF(H56>0," - "&H56&" x Switch"&CHAR(10),"")& IF(H57>0," - "&H57&" x Laptops"&CHAR(10),"")& IF(H58>0," - "&H58&" x Kartendrucker"&CHAR(10),"")& IF(H63>0," - "&H63&" x iPad"&CHAR(10),"")& IF(H59>0," - "&H59&" x Laserdrucker"&CHAR(10),"")& IF(H60>0," - "&H60&" x Thermodrucker"&CHAR(10),"")& IF(H61>0," - "&H61&" x Scanner"&CHAR(10),"")& IF(H62>0," - "&H62&" x Handheld Scanner"&CHAR(10),""), "")& IF(SUM(H65:H73)>0, $A$64&CHAR(10)& IF(H65>0," - "&H65&" x Router"&CHAR(10),"")& IF(H66>0," - "&H66&" x Switch"&CHAR(10),"")& IF(H67>0," - "&H67&" x Laptops"&CHAR(10),"")& IF(H68>0," - "&H68&" x Kartendrucker"&CHAR(10),"")& IF(H73>0," - "&H73&" x iPad"&CHAR(10),"")& IF(H69>0," - "&H69&" x Laserdrucker"&CHAR(10),"")& IF(H70>0," - "&H70&" x Thermodrucker"&CHAR(10),"")& IF(H71>0," - "&H71&" x Scanner"&CHAR(10),"")& IF(H72>0," - "&H72&" x Handheld Scanner"&CHAR(10),""), "") | I3: =IF(SUM(I5:I13)>0, $A$4&CHAR(10)& IF(I5>0," - "&I5&" x Router"&CHAR(10),"")& IF(I6>0," - "&I6&" x Switch"&CHAR(10),"")& IF(I7>0," - "&I7&" x Laptops"&CHAR(10),"")& IF(I8>0," - "&I8&" x Kartendrucker"&CHAR(10),"")& IF(I13>0," - "&I13&" x iPad"&CHAR(10),"")& IF(I9>0," - "&I9&" x Laserdrucker"&CHAR(10),"")& IF(I10>0," - "&I10&" x Thermodrucker"&CHAR(10),"")& IF(I11>0," - "&I11&" x Scanner"&CHAR(10),"")& IF(I12>0," - "&I12&" x Handheld Scanner"&CHAR(10),""), "")& IF(SUM(I15:I23)>0, $A$14&CHAR(10)& IF(I15>0," - "&I15&" x Router"&CHAR(10),"")& IF(I16>0," - "&I16&" x Switch"&CHAR(10),"")& IF(I17>0," - "&I17&" x Laptops"&CHAR(10),"")& IF(I18>0," - "&I18&" x Kartendrucker"&CHAR(10),"")& IF(I23>0," - "&I23&" x iPad"&CHAR(10),"")& IF(I19>0," - "&I19&" x Laserdrucker"&CHAR(10),"")& IF(I20>0," - "&I20&" x Thermodrucker"&CHAR(10),"")& IF(I21>0," - "&I21&" x Scanner"&CHAR(10),"")& IF(I22>0," - "&I22&" x Handheld Scanner"&CHAR(10),""), "")& IF(SUM(I25:I33)>0, $A$24&CHAR(10)& IF(I25>0," - "&I25&" x Router"&CHAR(10),"")& IF(I26>0," - "&I26&" x Switch"&CHAR(10),"")& IF(I27>0," - "&I27&" x Laptops"&CHAR(10),"")& IF(I28>0," - "&I28&" x Kartendrucker"&CHAR(10),"")& IF(I33>0," - "&I33&" x iPad"&CHAR(10),"")& IF(I29>0," - "&I29&" x Laserdrucker"&CHAR(10),"")& IF(I30>0," - "&I30&" x Thermodrucker"&CHAR(10),"")& IF(I31>0," - "&I31&" x Scanner"&CHAR(10),"")& IF(I32>0," - "&I32&" x Handheld Scanner"&CHAR(10),""), "")& IF(SUM(I35:I43)>0, $A$34&CHAR(10)& IF(I35>0," - "&I35&" x Router"&CHAR(10),"")& IF(I36>0," - "&I36&" x Switch"&CHAR(10),"")& IF(I37>0," - "&I37&" x Laptops"&CHAR(10),"")& IF(I38>0," - "&I38&" x Kartendrucker"&CHAR(10),"")& IF(I43>0," - "&I43&" x iPad"&CHAR(10),"")& IF(I39>0," - "&I39&" x Laserdrucker"&CHAR(10),"")& IF(I40>0," - "&I40&" x Thermodrucker"&CHAR(10),"")& IF(I41>0," - "&I41&" x Scanner"&CHAR(10),"")& IF(I42>0," - "&I42&" x Handheld Scanner"&CHAR(10),""), "")& IF(SUM(I45:I53)>0, $A$44&CHAR(10)& IF(I45>0," - "&I45&" x Router"&CHAR(10),"")& IF(I46>0," - "&I46&" x Switch"&CHAR(10),"")& IF(I47>0," - "&I47&" x Laptops"&CHAR(10),"")& IF(I48>0," - "&I48&" x Kartendrucker"&CHAR(10),"")& IF(I53>0," - "&I53&" x iPad"&CHAR(10),"")& IF(I49>0," - "&I49&" x Laserdrucker"&CHAR(10),"")& IF(I50>0," - "&I50&" x Thermodrucker"&CHAR(10),"")& IF(I51>0," - "&I51&" x Scanner"&CHAR(10),"")& IF(I52>0," - "&I52&" x Handheld Scanner"&CHAR(10),""), "")& IF(SUM(I55:I63)>0, $A$54&CHAR(10)& IF(I55>0," - "&I55&" x Router"&CHAR(10),"")& IF(I56>0," - "&I56&" x Switch"&CHAR(10),"")& IF(I57>0," - "&I57&" x Laptops"&CHAR(10),"")& IF(I58>0," - "&I58&" x Kartendrucker"&CHAR(10),"")& IF(I63>0," - "&I63&" x iPad"&CHAR(10),"")& IF(I59>0," - "&I59&" x Laserdrucker"&CHAR(10),"")& IF(I60>0," - "&I60&" x Thermodrucker"&CHAR(10),"")& IF(I61>0," - "&I61&" x Scanner"&CHAR(10),"")& IF(I62>0," - "&I62&" x Handheld Scanner"&CHAR(10),""), "")& IF(SUM(I65:I73)>0, $A$64&CHAR(10)& IF(I65>0," - "&I65&" x Router"&CHAR(10),"")& IF(I66>0," - "&I66&" x Switch"&CHAR(10),"")& IF(I67>0," - "&I67&" x Laptops"&CHAR(10),"")& IF(I68>0," - "&I68&" x Kartendrucker"&CHAR(10),"")& IF(I73>0," - "&I73&" x iPad"&CHAR(10),"")& IF(I69>0," - "&I69&" x Laserdrucker"&CHAR(10),"")& IF(I70>0," - "&I70&" x Thermodrucker"&CHAR(10),"")& IF(I71>0," - "&I71&" x Scanner"&CHAR(10),"")& IF(I72>0," - "&I72&" x Handheld Scanner"&CHAR(10),""), "") | ... K3: =IF(SUM(K5:K13)>0, $A$4&CHAR(10)& IF(K5>0," - "&K5&" x Router"&CHAR(10),"")& IF(K6>0," - "&K6&" x Switch"&CHAR(10),"")& IF(K7>0," - "&K7&" x Laptops"&CHAR(10),"")& IF(K8>0," - "&K8&" x Kartendrucker"&CHAR(10),"")& IF(K13>0," - "&K13&" x iPad"&CHAR(10),"")& IF(K9>0," - "&K9&" x Laserdrucker"&CHAR(10),"")& IF(K10>0," - "&K10&" x Thermodrucker"&CHAR(10),"")& IF(K11>0," - "&K11&" x Scanner"&CHAR(10),"")& IF(K12>0," - "&K12&" x Handheld Scanner"&CHAR(10),""), "")& IF(SUM(K15:K23)>0, $A$14&CHAR(10)& IF(K15>0," - "&K15&" x Router"&CHAR(10),"")& IF(K16>0," - "&K16&" x Switch"&CHAR(10),"")& IF(K17>0," - "&K17&" x Laptops"&CHAR(10),"")& IF(K18>0," - "&K18&" x Kartendrucker"&CHAR(10),"")& IF(K23>0," - "&K23&" x iPad"&CHAR(10),"")& IF(K19>0," - "&K19&" x Laserdrucker"&CHAR(10),"")& IF(K20>0," - "&K20&" x Thermodrucker"&CHAR(10),"")& IF(K21>0," - "&K21&" x Scanner"&CHAR(10),"")& IF(K22>0," - "&K22&" x Handheld Scanner"&CHAR(10),""), "")& IF(SUM(K25:K33)>0, $A$24&CHAR(10)& IF(K25>0," - "&K25&" x Router"&CHAR(10),"")& IF(K26>0," - "&K26&" x Switch"&CHAR(10),"")& IF(K27>0," - "&K27&" x Laptops"&CHAR(10),"")& IF(K28>0," - "&K28&" x Kartendrucker"&CHAR(10),"")& IF(K33>0," - "&K33&" x iPad"&CHAR(10),"")& IF(K29>0," - "&K29&" x Laserdrucker"&CHAR(10),"")& IF(K30>0," - "&K30&" x Thermodrucker"&CHAR(10),"")& IF(K31>0," - "&K31&" x Scanner"&CHAR(10),"")& IF(K32>0," - "&K32&" x Handheld Scanner"&CHAR(10),""), "")& IF(SUM(K35:K43)>0, $A$34&CHAR(10)& IF(K35>0," - "&K35&" x Router"&CHAR(10),"")& IF(K36>0," - "&K36&" x Switch"&CHAR(10),"")& IF(K37>0," - "&K37&" x Laptops"&CHAR(10),"")& IF(K38>0," - "&K38&" x Kartendrucker"&CHAR(10),"")& IF(K43>0," - "&K43&" x iPad"&CHAR(10),"")& IF(K39>0," - "&K39&" x Laserdrucker"&CHAR(10),"")& IF(K40>0," - "&K40&" x Thermodrucker"&CHAR(10),"")& IF(K41>0," - "&K41&" x Scanner"&CHAR(10),"")& IF(K42>0," - "&K42&" x Handheld Scanner"&CHAR(10),""), "")& IF(SUM(K45:K53)>0, $A$44&CHAR(10)& IF(K45>0," - "&K45&" x Router"&CHAR(10),"")& IF(K46>0," - "&K46&" x Switch"&CHAR(10),"")& IF(K47>0," - "&K47&" x Laptops"&CHAR(10),"")& IF(K48>0," - "&K48&" x Kartendrucker"&CHAR(10),"")& IF(K53>0," - "&K53&" x iPad"&CHAR(10),"")& IF(K49>0," - "&K49&" x Laserdrucker"&CHAR(10),"")& IF(K50>0," - "&K50&" x Thermodrucker"&CHAR(10),"")& IF(K51>0," - "&K51&" x Scanner"&CHAR(10),"")& IF(K52>0," - "&K52&" x Handheld Scanner"&CHAR(10),""), "")& IF(SUM(K55:K63)>0, $A$54&CHAR(10)& IF(K55>0," - "&K55&" x Router"&CHAR(10),"")& IF(K56>0," - "&K56&" x Switch"&CHAR(10),"")& IF(K57>0," - "&K57&" x Laptops"&CHAR(10),"")& IF(K58>0," - "&K58&" x Kartendrucker"&CHAR(10),"")& IF(K63>0," - "&K63&" x iPad"&CHAR(10),"")& IF(K59>0," - "&K59&" x Laserdrucker"&CHAR(10),"")& IF(K60>0," - "&K60&" x Thermodrucker"&CHAR(10),"")& IF(K61>0," - "&K61&" x Scanner"&CHAR(10),"")& IF(K62>0," - "&K62&" x Handheld Scanner"&CHAR(10),""), "")& IF(SUM(K65:K73)>0, $A$64&CHAR(10)& IF(K65>0," - "&K65&" x Router"&CHAR(10),"")& IF(K66>0," - "&K66&" x Switch"&CHAR(10),"")& IF(K67>0," - "&K67&" x Laptops"&CHAR(10),"")& IF(K68>0," - "&K68&" x Kartendrucker"&CHAR(10),"")& IF(K73>0," - "&K73&" x iPad"&CHAR(10),"")& IF(K69>0," - "&K69&" x Laserdrucker"&CHAR(10),"")& IF(K70>0," - "&K70&" x Thermodrucker"&CHAR(10),"")& IF(K71>0," - "&K71&" x Scanner"&CHAR(10),"")& IF(K72>0," - "&K72&" x Handheld Scanner"&CHAR(10),""), "")
A4: Montag 05.01. | N4: Aktueller Bestand
A5: Router | L5: =SUM(B5:K5) -> 0 | M5: Router | N5: =Bestand!$F$13 -(L5) -> 9
A6: Switch | L6: =SUM(B6:K6) -> 0 | M6: Switch | N6: =Bestand!$F$14 -(L6) -> 7
A7: Laptop | L7: =SUM(B7:K7) -> 0 | M7: Laptop | N7: =Bestand!$F$2 -(L7) -> 32
A8: Kartendrucker | L8: =SUM(B8:K8) -> 0 | M8: Kartendrucker | N8: =Bestand!$F$3 -(L8) -> 12
A9: Laserdrucker | L9: =SUM(B9:K9) -> 0 | M9: Laserdrucker | N9: =Bestand!$F$8 -(L9) -> 33
A10: Thermodrucker | L10: =SUM(B10:K10) -> 0 | M10: Thermodrucker | N10: =Bestand!$F$9 -(L10) -> 12
A11: Scanner | L11: =SUM(B11:K11) -> 0 | M11: Scanner | N11: =Bestand!$F$10 -(L11) -> 29
A12: Handheld | L12: =SUM(B12:K12) -> 0 | M12: Handheld | N12: =Bestand!$F$11 -(L12) -> 24
A13: Ipad | L13: =SUM(B13:K13) -> 0 | M13: Ipad | N13: =Bestand!$F$12 -(L13) -> 31
A14: Dienstag 06.01. | L14: Dienstag
A15: Router | L15: =SUM(B15:K15) -> 0 | M15: Router | N15: =Bestand!$F$13 -(L15) -> 9
A16: Switch | L16: =SUM(B16:K16) -> 0 | M16: Switch | N16: =Bestand!$F$14 -(L16) -> 7
A17: Laptop | L17: =SUM(B17:K17) -> 0 | M17: Laptop | N17: =Bestand!$F$2 -(L17) -> 32
A18: Kartendrucker | L18: =SUM(B18:K18) -> 0 | M18: Kartendrucker | N18: =Bestand!$F$3 -(L18) -> 12
A19: Laserdrucker | L19: =SUM(B19:K19) -> 0 | M19: Laserdrucker | N19: =Bestand!$F$8 -(L19) -> 33
A20: Thermodrucker | L20: =SUM(B20:K20) -> 0 | M20: Thermodrucker | N20: =Bestand!$F$9 -(L20) -> 12
A21: Scanner | L21: =SUM(B21:K21) -> 0 | M21: Scanner | N21: =Bestand!$F$10 -(L21) -> 29
A22: Handheld | L22: =SUM(B22:K22) -> 0 | M22: Handheld | N22: =Bestand!$F$11 -(L22) -> 24
A23: Ipad | L23: =SUM(B23:K23) -> 0 | M23: Ipad | N23: =Bestand!$F$12 -(L23) -> 31
A24: Mittwoch 07.01. | L24: Mittwoch
A25: Router | L25: =SUM(B25:K25) -> 0 | M25: Router | N25: =Bestand!$F$13 -(L25) -> 9
A26: Switch | L26: =SUM(B26:K26) -> 0 | M26: Switch | N26: =Bestand!$F$14 -(L26) -> 7
A27: Laptop | L27: =SUM(B27:K27) -> 0 | M27: Laptop | N27: =Bestand!$F$2 -(L27) -> 32
A28: Kartendrucker | L28: =SUM(B28:K28) -> 0 | M28: Kartendrucker | N28: =Bestand!$F$3 -(L28) -> 12
A29: Laserdrucker | L29: =SUM(B29:K29) -> 0 | M29: Laserdrucker | N29: =Bestand!$F$8 -(L29) -> 33
A30: Thermodrucker | L30: =SUM(B30:K30) -> 0 | M30: Thermodrucker | N30: =Bestand!$F$9 -(L30) -> 12
A31: Scanner | L31: =SUM(B31:K31) -> 0 | M31: Scanner | N31: =Bestand!$F$10 -(L31) -> 29
A32: Handheld | L32: =SUM(B32:K32) -> 0 | M32: Handheld | N32: =Bestand!$F$11 -(L32) -> 24
A33: Ipad | L33: =SUM(B33:K33) -> 0 | M33: Ipad | N33: =Bestand!$F$12 -(L33) -> 31
A34: Donnerstag 08.01 | L34: Donnerstag
A35: Router | L35: =SUM(B35:K35) -> 0 | M35: Router | N35: =Bestand!$F$13 -(L35) -> 9
A36: Switch | L36: =SUM(B36:K36) -> 0 | M36: Switch | N36: =Bestand!$F$14 -(L36) -> 7
A37: Laptop | L37: =SUM(B37:K37) -> 0 | M37: Laptop | N37: =Bestand!$F$2 -(L37) -> 32
A38: Kartendrucker | L38: =SUM(B38:K38) -> 0 | M38: Kartendrucker | N38: =Bestand!$F$3 -(L38) -> 12
A39: Laserdrucker | L39: =SUM(B39:K39) -> 0 | M39: Laserdrucker | N39: =Bestand!$F$8 -(L39) -> 33
A40: Thermodrucker | L40: =SUM(B40:K40) -> 0 | M40: Thermodrucker | N40: =Bestand!$F$9 -(L40) -> 12
...

Sheet KW 2 (05.01. 11.01.)
A1: Kunde
A2: Mitarbeiter
